2022-08-02 03:42:12,380 INFO    StreamThr :56874 [internal.py:wandb_internal():93] W&B internal server running at pid: 56874, started at: 2022-08-02 03:42:12.380381
2022-08-02 03:42:12,383 DEBUG   HandlerThread:56874 [handler.py:handle_request():140] handle_request: status
2022-08-02 03:42:12,384 DEBUG   SenderThread:56874 [sender.py:send_request():250] send_request: status
2022-08-02 03:42:12,385 DEBUG   SenderThread:56874 [sender.py:send():236] send: header
2022-08-02 03:42:12,386 INFO    WriterThread:56874 [datastore.py:open_for_write():75] open: /home/harry/multi_nodes_training/Distributed_Training_Single_and_Multi_machine/pytorch_lightning_distributed_training/wandb/run-20220802_034212-mhq58rcr/run-mhq58rcr.wandb
2022-08-02 03:42:12,395 DEBUG   SenderThread:56874 [sender.py:send():236] send: run
2022-08-02 03:42:12,396 INFO    SenderThread:56874 [sender.py:_maybe_setup_resume():494] checking resume status for tranrick/Multi-node-training/mhq58rcr
2022-08-02 03:42:12,573 ERROR   SenderThread:56874 [internal_api.py:execute():161] 404 response executing GraphQL.
2022-08-02 03:42:12,573 ERROR   SenderThread:56874 [internal_api.py:execute():162] {"errors":[{"message":"project not found","path":["upsertBucket"]}],"data":{"upsertBucket":null}}
2022-08-02 03:42:13,396 INFO    HandlerThread:56874 [handler.py:finish():806] shutting down handler
2022-08-02 03:42:13,396 INFO    WriterThread:56874 [datastore.py:close():279] close: /home/harry/multi_nodes_training/Distributed_Training_Single_and_Multi_machine/pytorch_lightning_distributed_training/wandb/run-20220802_034212-mhq58rcr/run-mhq58rcr.wandb
2022-08-02 03:42:13,396 ERROR   StreamThr :56874 [internal.py:wandb_internal():165] Thread SenderThread:
Traceback (most recent call last):
  File "/anaconda/envs/MVQG/lib/python3.7/site-packages/wandb/sdk/lib/retry.py", line 108, in __call__
    result = self._call_fn(*args, **kwargs)
  File "/anaconda/envs/MVQG/lib/python3.7/site-packages/wandb/sdk/internal/internal_api.py", line 158, in execute
    return self.client.execute(*args, **kwargs)
  File "/anaconda/envs/MVQG/lib/python3.7/site-packages/wandb/vendor/gql-0.2.0/wandb_gql/client.py", line 52, in execute
    result = self._get_result(document, *args, **kwargs)
  File "/anaconda/envs/MVQG/lib/python3.7/site-packages/wandb/vendor/gql-0.2.0/wandb_gql/client.py", line 60, in _get_result
    return self.transport.execute(document, *args, **kwargs)
  File "/anaconda/envs/MVQG/lib/python3.7/site-packages/wandb/vendor/gql-0.2.0/wandb_gql/transport/requests.py", line 39, in execute
    request.raise_for_status()
  File "/anaconda/envs/MVQG/lib/python3.7/site-packages/requests/models.py", line 1022, in raise_for_status
    raise HTTPError(http_error_msg, response=self)
requests.exceptions.HTTPError: 404 Client Error: Not Found for url: https://api.wandb.ai/graphql

During handling of the above exception, another exception occurred:

Traceback (most recent call last):
  File "/anaconda/envs/MVQG/lib/python3.7/site-packages/wandb/apis/normalize.py", line 25, in wrapper
    return func(*args, **kwargs)
  File "/anaconda/envs/MVQG/lib/python3.7/site-packages/wandb/sdk/internal/internal_api.py", line 1341, in upsert_run
    response = self.gql(mutation, variable_values=variable_values, **kwargs)
  File "/anaconda/envs/MVQG/lib/python3.7/site-packages/wandb/sdk/lib/retry.py", line 124, in __call__
    if not check_retry_fn(e):
  File "/anaconda/envs/MVQG/lib/python3.7/site-packages/wandb/util.py", line 887, in no_retry_auth
    raise CommError("Permission denied, ask the project owner to grant you access")
wandb.errors.CommError: Permission denied, ask the project owner to grant you access

During handling of the above exception, another exception occurred:

Traceback (most recent call last):
  File "/anaconda/envs/MVQG/lib/python3.7/site-packages/wandb/sdk/internal/internal_util.py", line 51, in run
    self._run()
  File "/anaconda/envs/MVQG/lib/python3.7/site-packages/wandb/sdk/internal/internal_util.py", line 102, in _run
    self._process(record)
  File "/anaconda/envs/MVQG/lib/python3.7/site-packages/wandb/sdk/internal/internal.py", line 310, in _process
    self._sm.send(record)
  File "/anaconda/envs/MVQG/lib/python3.7/site-packages/wandb/sdk/internal/sender.py", line 238, in send
    send_handler(record)
  File "/anaconda/envs/MVQG/lib/python3.7/site-packages/wandb/sdk/internal/sender.py", line 696, in send_run
    self._init_run(run, config_value_dict)
  File "/anaconda/envs/MVQG/lib/python3.7/site-packages/wandb/sdk/internal/sender.py", line 734, in _init_run
    commit=run.git.last_commit or None,
  File "/anaconda/envs/MVQG/lib/python3.7/site-packages/wandb/apis/normalize.py", line 61, in wrapper
    raise CommError(message, err).with_traceback(sys.exc_info()[2])
  File "/anaconda/envs/MVQG/lib/python3.7/site-packages/wandb/apis/normalize.py", line 25, in wrapper
    return func(*args, **kwargs)
  File "/anaconda/envs/MVQG/lib/python3.7/site-packages/wandb/sdk/internal/internal_api.py", line 1341, in upsert_run
    response = self.gql(mutation, variable_values=variable_values, **kwargs)
  File "/anaconda/envs/MVQG/lib/python3.7/site-packages/wandb/sdk/lib/retry.py", line 124, in __call__
    if not check_retry_fn(e):
  File "/anaconda/envs/MVQG/lib/python3.7/site-packages/wandb/util.py", line 887, in no_retry_auth
    raise CommError("Permission denied, ask the project owner to grant you access")
wandb.errors.CommError: Permission denied, ask the project owner to grant you access
